Workbook

Sheet README
A1: Project MarginSpring — D2 Data Ingestion & Governance Dataset
A2: Version v1.3 · built 2026-10-23 · Team J (owner: James Mathew) · ANCP Module 2
A4: What this workbook is
A5: The cleaned, versioned dataset for D2. Raw files are never edited; every number here traces to a Source_Log id.
A7: Sheets
A8: Source_Log — every source: publisher, URL, period, date accessed, licence/terms, verification note
A9: Harmonisation — canonical variable definitions and how each firm / Bloomberg labels them
A10: Quarterly_Panel — one row per firm-quarter: Wipro Q1 FY15–Q2 FY27 (50), Infosys Q4 FY19–Q1 FY27, TCS Q4 FY22–Q2 FY27, HCLTech Q2 FY25–Q2 FY27, LTIMindtree Q2 FY23–Q1 FY27, Tech Mahindra Q4 FY24–Q2 FY27. Columns Q–S are D4 controls: wage-hike quarter flag, USD/INR quarterly average, one-off flag
A11: Wage_Hikes — salary-hike effective dates and first fiscal quarter of impact (Wipro FY21–FY27, Infosys FY21–FY27, TCS FY25–FY27)
A12: FX_USDINR — monthly USD/INR (US Federal Reserve G.5 via FRED), Jan 2014–Sep 2026, mapped to fiscal quarters
A13: TCS_Commentary — what TCS management said about utilisation, bench and capacity each quarter around the June 2025 policy
A14: Margin_Walks — management statements of margin change by driver, tiered A/B/C
... A31: Peer data now comes from company filings (v1.1). If refreshed Bloomberg files arrive later, save them to raw/bloomberg_v1, rerun, and use them as a third source; bump the version and log it in Changelog.

Sheet Source_Log
A1: source_id | B1: publisher | C1: document | D1: url | E1: periods_covered | F1: source_type | G1: licence_terms | H1: used_for | I1: verification_note | J1: date_accessed
A2: S01 | B2: Bloomberg L.P. (via XIME terminal) | C2: 26 Excel exports: FA pages (BDH) for WPRO IN; KPI Comparison 'IT Services' (BQL); Company Financial multi-period (BQL) | D2: Bloomberg Terminal (no URL) | E2: FY2015–FY2028E annual; CY2025Q2–CY2027Q1 quarterly | F2: Licensed database | G2: Bloomberg subscription terms: internal academic use; raw data not to be republished | H2: Financial panel (annual), peer KPI panel (once refreshed) | I2: 97.7% of requested cells unevaluated; see Bloomberg_File_Audit | J2: 2026-10-23
A3: S02 | B3: Wipro Ltd | C3: Analyst datasheet Q2 FY27 | D3: https://www.wipro.com/content/dam/nexus/en/investor/quarterly-results/2026-2027/q2fy27/datasheet-q2fy27.pdf | E3: Q1 FY26–Q2 FY27 | F3: Company disclosure (primary) | G3: Public investor disclosure; academic use | H3: Wipro capacity & margin panel | I3: Matches D1 table for all 5 overlapping quarters | J3: 2026-10-23
A4: S03 | B4: Wipro Ltd | C4: Analyst datasheet Q4 FY25 | D4: https://www.wipro.com/content/dam/nexus/en/investor/quarterly-results/2024-2025/q4fy25/datasheet-q4fy25.pdf | E4: Q4 FY24–Q4 FY25 | F4: Company disclosure (primary) | G4: Public investor disclosure; academic use | H4: Wipro panel | J4: 2026-10-23
A5: S04 | B5: Wipro Ltd | C5: Analyst datasheet Q3 FY24 | D5: https://www.wipro.com/content/dam/nexus/en/investor/quarterly-results/2023-2024/q3fy24/datasheet-q3fy24.pdf | E5: Q2–Q3 FY24 | F5: Company disclosure (primary) | G5: Public investor disclosure; academic use | H5: Wipro panel (fills Q3 FY24); cross-checks Q2 FY24 vs S05 | I5: Q2 FY24 identical to S05 | J5: 2026-10-23
A6: S05 | B6: Wipro Ltd | C6: Analyst datasheet Q2 FY24 | D6: https://www.wipro.com/content/dam/nexus/en/investor/quarterly-results/2023-2024/q2fy24/datasheet-q2fy24.pdf | E6: Q1 FY23–Q2 FY24 | F6: Company disclosure (primary) | G6: Public investor disclosure; academic use | H6: Wipro panel | J6: 2026-10-23
A7: S06 | B7: Wipro Ltd | C7: Analyst datasheet Q4 FY22 | D7: https://www.wipro.com/content/dam/nexus/en/investor/quarterly-results/2021-2022/q4fy22/analyst-data-sheet-q4-fy22.pdf | E7: Q4 FY21–Q4 FY22 | F7: Company disclosure (primary) | G7: Public investor disclosure; academic use | H7: Wipro panel (incl. gross utilisation) | J7: 2026-10-23
A8: S07 | B8: Wipro Ltd | C8: Analyst datasheet Q3 FY21 | D8: https://www.wipro.com/content/dam/nexus/en/investor/quarterly-results/2020-2021/q3fy21/analyst-data-sheet-q3-fy21..pdf | E8: Q3 FY21 | F8: Company disclosure (primary) | G8: Public investor disclosure; academic use | H8: Wipro panel (fills Q3 FY21) | J8: 2026-10-23
A9: S08 | B9: Wipro Ltd | C9: Analyst datasheet Q2 FY21 | D9: https://www.wipro.com/content/dam/nexus/en/investor/quarterly-results/2020-2021/q2fy21/analyst-data-sheet-q2-fy21.pdf | E9: Q1 FY20–Q2 FY21 | F9: Company disclosure (primary) | G9: Public investor disclosure; academic use | H9: Wipro panel | J9: 2026-10-23
A10: S09 | B10: Wipro Ltd | C10: Investor quarterly-results index (links to all datasheets FY12–FY27) | D10: https://www.wipro.com/investors/quarterly-results/ | E10: FY12–FY27 | F10: Company website | G10: Public | H10: Locating datasheets for back-fill to 40 quarters | J10: 2026-10-23
A11: S10 | B11: Tata Consultancy Services | C11: Fact sheet Q2 FY27 | D11: https://www.tcs.com/content/dam/tcs/investor-relations/financial-statements/2026-27/q2/Presentations/Q2%202026-27%20Fact%20Sheet.pdf | E11: Q1 FY26–Q2 FY27 | F11: Company disclosure (primary) | G11: Public investor disclosure; academic use | H11: TCS margin & headcount panel | I11: Utilisation not disclosed | J11: 2026-10-23
A12: S11 | B12: HCL Technologies | C12: Investor release Q2 FY27 | D12: https://www.hcltech.com/sites/default/files/document/open/quarter-results/2026-10/hcltech-Q2-fy27-Investor-release.pdf | E12: Q2 FY26–Q2 FY27 | F12: Company disclosure (primary) | G12: Public investor disclosure; academic use | H12: HCLTech margin, headcount, attrition | I12: Utilisation not disclosed | J12: 2026-10-23
A13: S12 | B13: Infosys Ltd | C13: Fact sheet Q1 FY27 | D13: https://www.infosys.com/investors/reports-filings/quarterly-results/2026-2027/q1/documents/fact-sheet.pdf | E13: Q1 FY26, Q4 FY26, Q1 FY27 | F13: Company disclosure (primary) | G13: Public investor disclosure; academic use | H13: Infosys panel | I13: Q4 FY26 margin 20.9 (USD table) vs 21.0 (INR table) | J13: 2026-10-23
A14: S13 | B14: Infosys Ltd | C14: Fact sheet Q2 FY26 | D14: https://www.infosys.com/investors/reports-filings/quarterly-results/2025-2026/q2/documents/fact-sheet.pdf | E14: Q2 FY25, Q1 FY26, Q2 FY26 | F14: Company disclosure (primary) | G14: Public investor disclosure; academic use | H14: Infosys panel | I14: Q1 FY26 identical to S12 | J14: 2026-10-23
A15: S14 | B15: Infosys Ltd via The Motley Fool | C15: Q1 FY27 earnings call transcript (23 Jul 2026) | D15: https://www.fool.com/earnings/call-transcripts/2026/07/23/infosys-infy-q1-2027-earnings-call-transcript/ | E15: Q1 FY27 | F15: Transcript (third-party) | G15: Quoted sparingly; academic use | H15: Margin walk | I15: Utilisation +1.9 pts confirmed vs S12 (83.0→84.9) | J15: 2026-10-23
A16: S15 | B16: Infosys Ltd | C16: Q4 FY25 earnings call transcript | D16: https://www.infosys.com/investors/reports-filings/quarterly-results/2024-2025/q4/documents/transcripts/earningscall.pdf | E16: Q4 FY25 | F16: Transcript (company) | G16: Quoted sparingly; academic use | H16: Margin walk | J16: 2026-10-23
A17: S16 | B17: Infosys Ltd | C17: Q1 FY23 earnings call transcript (24 Jul 2022); also SEC Form 6-K exv99w05 | D17: https://www.infosys.com/investors/reports-filings/quarterly-results/2022-2023/q1/documents/transcripts/earningscall.pdf | E17: Q1 FY23 | F17: Transcript (company) | G17: Quoted sparingly; academic use | H17: Margin walk (Tier A) | I17: Two copies agree (infosys.com and SEC 6-K https://sec.gov/Archives/edgar/data/1067491/000106749122000036/exv99w05.htm) | J17: 2026-10-23
A18: S17 | B18: Infosys Ltd | C18: Q3 FY21 earnings call transcript | D18: https://www.infosys.com/investors/reports-filings/quarterly-results/2020-2021/q3/documents/transcripts/earningscall.pdf | E18: Q3 FY21 | F18: Transcript (company) | G18: Quoted sparingly; academic use | H18: Margin walk (Tier B) | J18: 2026-10-23
A19: S18 | B19: Infosys Ltd | C19: Q3 FY25 earnings call transcript | D19: https://www.infosys.com/investors/reports-filings/quarterly-results/2024-2025/q3/documents/transcripts/earningscall.pdf | E19: Q3 FY25 | F19: Transcript (company) | G19: Quoted sparingly; academic use | H19: Margin walk (Tier C) | J19: 2026-10-23
A20: S19 | B20: Infosys Ltd | C20: Q2 FY25 earnings call transcript | D20: https://www.infosys.com/investors/reports-filings/quarterly-results/2024-2025/q2/documents/transcripts/earningscall.pdf | E20: Q2 FY25 | F20: Transcript (company) | G20: Quoted sparingly; academic use | H20: Margin walk (Tier C) | I20: Utilisation 85.9% matches S13 | J20: 2026-10-23
A21: S20 | B21: Infosys Ltd (SEC Form 6-K) | C21: Q1 FY26 earnings call transcript (23 Jul 2025) | D21: https://www.sec.gov/Archives/edgar/data/1067491/000106749125000022/exv99w05.htm | E21: Q1 FY26 | F21: Regulatory filing | G21: Public filing; academic use | H21: Margin walk (Tier C) | I21: Utilisation 85.2% matches S12/S13 | J21: 2026-10-23
A22: S21 | B22: Infosys Ltd | C22: Q3 FY23 earnings call transcript | D22: https://www.infosys.com/investors/reports-filings/quarterly-results/2022-2023/q3/documents/transcripts/earningscall.pdf | E22: Q3 FY23 | F22: Transcript (company) | G22: Quoted sparingly; academic use | H22: Margin walk (Tier B) | J22: 2026-10-23
A23: S22 | B23: Infosys Ltd (SEC Form 6-K) | C23: Q2 FY24 media call transcript (12 Oct 2023) | D23: https://www.sec.gov/Archives/edgar/data/1067491/000106749123000057/exv99w05.htm | E23: Q2 FY24 | F23: Regulatory filing | G23: Public filing; academic use | H23: Margin walk (Tier B) | J23: 2026-10-23
A24: S23 | B24: Tata Consultancy Services | C24: Q4 FY25 earnings call transcript (10 Apr 2025) | D24: https://www.tcs.com/content/dam/tcs/investor-relations/financial-statements/2024-25/q4/Management Commentary/Transcript of the Q4 2024-25 Earnings Conference Call held at 1900 hrs IST on Apr 10, 2025.pdf | E24: Q4 FY25, FY25 | F24: Transcript (company) | G24: Quoted sparingly; academic use | H24: Margin walk (Tier C) | I24: Named drivers do not sum to reported change | J24: 2026-10-23
A25: S24 | B25: Wipro Ltd via The Motley Fool | C25: Q1 FY21 earnings call transcript (14 Jul 2020) | D25: https://www.fool.com/earnings/call-transcripts/2020/07/14/wipro-limited-wit-q1-2021-earnings-call-transcript.aspx | E25: Q1 FY21 | F25: Transcript (third-party, auto-generated) | G25: Quoted sparingly; academic use | H25: Margin walk (Tier B) | I25: Auto-transcript; components do not reconcile cleanly | J25: 2026-10-23
A26: S25 | B26: Bank of Baroda Capital Markets | C26: HCLTech Q1 FY26 result review (15 Jul 2025) | D26: https://www.barodaetrade.com/Reports/HCLTechnologies-Q1FY26ResultReview15Jul25-Research.pdf | E26: Q1 FY26 | F26: Broker research (secondary) | G26: Publicly posted research; quote only | H26: Margin walk (Tier A) | I26: Agrees with D1 source S33 (80 bps) | J26: 2026-10-23
A27: S26 | B27: Outlook Business | C27: HCLTech shares in focus after Q1 underwhelms (Jul 2025) | D27: https://www.outlookbusiness.com/markets/hcltech-shares-in-focus-after-q1-underwhelms-margin-misses | E27: Q1 FY26 | F27: News (secondary) | G27: Quote only | H27: HCLTech Q1 FY26 margin level | I27: Reports 160 bps fall; Emkay says 170 bps | J27: 2026-10-23
A28: S27 | B28: AlphaStreet | C28: HCLTech Q2 FY24 earnings call insights | D28: https://alphastreet.com/india/hcl-technologies-limited-q2-fy24-earnings-conference-call-insights | E28: Q2 FY24 | F28: Call summary (secondary) | G28: Quote only | H28: Margin walk (Tier B) | J28: 2026-10-23
A29: S28 | B29: Sharekhan | C29: Tech Mahindra Q1 FY26 result note (16 Jul 2025) | D29: https://www.sharekhan.com/MediaGalary/docs/TechM-Jul16_2025-202507171645286735867.pdf | E29: Q1 FY26 | F29: Broker research (secondary) | G29: Publicly posted research; quote only | H29: TechM margin, utilisation (Tier C walk) | I29: Internal conflict: utilisation fall stated as 130 bps and 80 bps | J29: 2026-10-23
A30: S29 | B30: Multibagg | C30: Tech Mahindra Q2 FY27 results | D30: https://www.multibagg.ai/market-pulse/articles/tech-mahindra-q2-fy27-results-cmvaqmppj00052umtdvlhbclv | E30: Q1–Q2 FY27 | F30: News aggregator (secondary) | G30: Quote only | H30: TechM margin, headcount, attrition | I30: Single source; replace with TechM fact sheet | J30: 2026-10-23
A31: S30 | B31: ICICI Direct | C31: LTIMindtree Q2 FY26 result update | D31: https://www.icicidirect.com/mailcontent/idirect_ltim_q2fy26.pdf | E31: Q2 FY25, Q1–Q2 FY26 | F31: Broker research (secondary) | G31: Publicly posted research; quote only | H31: LTIM margin, headcount, attrition | I31: Single source; replace with LTIM fact sheet | J31: 2026-10-23
A32: S31 | B32: PSU Connect | C32: Wipro Q2 FY27: margin improves to 16.5% | D32: https://www.psuconnect.in/financial/wipro-q2-fy27-it-services-flat-qoq-margin-improves-to-16-5 | E32: Q2 FY27 | F32: News (secondary) | G32: Quote only | H32: Second source for Wipro Q2 FY27 margin | I32: Agrees with S02 | J32: 2026-10-23
A33: S32 | B33: Infosys Ltd (SEC Form 6-K) — cited in D1 | C33: Earnings call 2020: 80 bps margin from 2.4% utilisation increase | D33: https://www.sec.gov/Archives/edgar/data/1067491/000106749120000072/exv99w05.htm | E33: 2020 (quarter to confirm) | F33: Regulatory filing | G33: Public filing; academic use | H33: Margin walk (Tier A) | I33: Carried from D1; could not re-open this session (site not reachable) — re-verify quarter | J33: 2026-10-23
A34: S33 | B34: Business Standard — cited in D1 | C34: HCLTech Q1 FY26 results; lower utilisation 80 bps | D34: https://www.business-standard.com/markets/news/hcltech-sees-rating-downgrade-post-q1-results-guidance-disappointment-125071501441_1.html | E34: Q1 FY26 | F34: News (secondary) | G34: Quote only | H34: Second source for HCLTech Q1 FY26 walk | I34: Carried from D1 | J34: 2026-10-23
A35: S34 | B35: Sightsinplus — cited in D1 | C35: Wipro revised bench policy (Oct 2026) | D35: https://www.sightsinplus.com/news/industry-news/wipro-gives-employees-six-months-to-find-new-projects-revised-bench-policy/ | E35: Oct 2026 | F35: News (secondary) | G35: Quote only | H35: Policy event: Wipro 180-day window | I35: Carried from D1; second source pending | J35: 2026-10-23
A36: S35 | B36: Outlook Business — cited in D1 | C36: TCS caps bench time at 35 days | D36: https://www.outlookbusiness.com/corporate/tcs-caps-bench-time-at-35-days-under-new-deployment-policy | E36: Jun 2025 | F36: News (secondary) | G36: Quote only | H36: Policy event: TCS 35-business-day cap | I36: Carried from D1; second source = S40 | J36: 2026-10-23
A37: S36 | B37: Sightsinplus — cited in D1 | C37: TCS builds higher bench despite 2025 policy (Oct 2026) | D37: https://www.sightsinplus.com/news/industry-news/tcs-builds-higher-bench-increases-subcontracting-despite-2025-bench-policy/ | E37: Q2 FY27 | F37: News (secondary) | G37: Quote only | H37: Counter-evidence for TCS before/after | I37: Carried from D1 | J37: 2026-10-23
A38: S37 | B38: Webull — cited in D1 | C38: Wipro Q1 FY27 earnings call transcript (Jul 2026) | D38: https://www.webull.com/news/15239831956513792 | E38: Q1 FY27 | F38: Transcript (third-party) | G38: Quoted sparingly | H38: Target band 17–17.5%; stated drivers | I38: Carried from D1 | J38: 2026-10-23
A39: S38 | B39: Wipro Ltd — cited in D1 | C39: Press release, results for quarter ended 30 Sep 2026 (15 Oct 2026) | D39: https://www.wipro.com/newsroom/press-releases/2026/wipro-announces-results-for-the-quarter-ended-september-30-2026/ | E39: Q2 FY27 | F39: Company disclosure (primary) | G39: Public | H39: Second source for Wipro Q2 FY27 margin | I39: Agrees with S02 | J39: 2026-10-23
A40: S39 | B40: Storyboard18 — cited in D1 | C40: NITES complaint on TCS bench policy (Jul 2025) | D40: https://www.storyboard18.com/how-it-works/tcs-under-fire-for-new-bench-policy-nites-alleges-forced-exits-salary-refund-demands-75206.htm | E40: Jul 2025 | F40: News (secondary) | G40: Quote only | H40: Stakeholder / labour-relations context | I40: Carried from D1 | J40: 2026-10-23
...

Sheet Harmonisation
A1: canonical_variable | B1: definition | C1: unit | D1: Wipro label | E1: Infosys label | F1: TCS label | G1: HCLTech label | H1: LTIMindtree label | I1: Tech Mahindra label | J1: Bloomberg mnemonic | K1: harmonisation rule / caveat
A2: op_margin_pct | B2: Operating (EBIT) margin, % of revenue, as reported for the quarter | C2: % | D2: IT Services segment operating margin (datasheet 'Operating Margin %') | E2: Company operating margin (fact sheet) | F2: Company operating margin excl. exceptional items | G2: Company EBIT incl. restructuring; IT&BS segment EBIT in notes | H2: Company EBIT margin | I2: Company EBIT margin | J2: CB_IS_ADJ_OPERATING_MARGIN (adjusted, company level) / CB_IS_OPERATING_MARGIN | K2: Not like-for-like: Wipro is a segment margin. Compare changes (bps QoQ), not levels, across firms. Record basis in margin_basis.
A3: util_excl_trainees_pct | B3: Billable effort / total effort of delivery staff excluding trainees | C3: % | D3: 'Net Utilization (Excluding Trainees)' | E3: 'Utilization – excluding trainees' | F3: Not disclosed | G3: Not disclosed (dropped from releases) | H3: Reported in fact sheet (collect) | I3: Reported incl. trainees in notes; confirm | J3: UTILIZATION_RATE (definition varies by firm — check field notes on terminal) | K3: Primary capacity variable. Do not mix with incl-trainee series.
A4: util_gross_or_incl_trainees_pct | B4: Utilisation including trainees (Infosys) / gross utilisation (Wipro, to FY22) | C4: % | D4: 'Gross Utilization' (FY20–FY22 only) | E4: 'Utilization – including trainees' | F4: Not disclosed | G4: Not disclosed | H4: Check fact sheet | I4: 'Utilisation' (incl. trainees) | J4: — | K4: Secondary series; used only for robustness checks.
A5: headcount | B5: Closing total employees at quarter end | C5: persons | D5: 'Closing Employee Count' | E5: 'Total employees' | F5: 'Total Employee Base' | G5: 'Total headcount' | H5: Total headcount | I5: Total headcount | J5: NUM_OF_EMPLOYEES | K5: Includes BPO/BPS staff where firm does.
A6: vol_attrition_ttm_pct | B6: Voluntary attrition, trailing twelve months, IT services | C6: % | D6: 'Voluntary TTM (IT Services excl. DOP/BPS)' | E6: 'Voluntary attrition % (LTM, IT Services)' | F6: 'Attrition (LTM, IT Services)' | G6: Attrition LTM excl. involuntary & DPO | H6: Attrition LTM | I6: IT attrition LTM | J6: ATTRITION_RATE | K6: Definitions close; minor scope differences noted.
A7: it_rev_usd_mn | B7: IT services revenue in USD million | C7: USD mn | D7: 'IT Services Revenues ($Mn)' | E7: Revenue US$ mn (company) | F7: Revenue US$ mn (company) | G7: Revenue US$ mn | H7: Revenue US$ mn | I7: Revenue US$ mn | J7: SALES_REV_TURN (segment SEG0000403243 for Wipro IT Services) | K7: Wipro only collected in v1.0.
A8: cc_qoq_pct | B8: Sequential revenue growth in constant currency | C8: % | D8: 'Sequential Growth in Constant Currency' | E8: QoQ CC | F8: 'Q-o-Q Growth CC' | G8: QoQ CC | H8: QoQ CC | I8: QoQ CC | J8: Constant Currency Revenue Growth (%) in KPIC | K8: Control variable for D4 regression.
A9: util_bps | B9: Margin change attributed by management to utilisation, bps | C9: bps | D9: Earnings call | E9: Earnings call | F9: Earnings call | G9: Earnings call / broker note | H9: Earnings call | I9: Earnings call | J9: — | K9: Tier A = utilisation isolated; B = bundled with other levers; C = named only.
A10: fiscal_quarter | B10: Indian fiscal quarter label | C10: text | D10: Q1 = Apr–Jun | E10: same | F10: same | G10: same | H10: same | I10: same | J10: FPR 'YYYY Qn' with FYE='C' is calendar: CY2026 Q3 = Q2 FY27 | K10: Mapping implemented in ingest_bloomberg.calendar_to_wipro_fq()

Sheet Quarterly_Panel
A1: firm | B1: fiscal_quarter | C1: quarter_end | D1: op_margin_pct | E1: margin_basis | F1: util_excl_trainees_pct | G1: util_gross_or_incl_trainees_pct | H1: headcount | I1: vol_attrition_ttm_pct | J1: it_rev_usd_mn | K1: cc_qoq_pct | L1: source_id | M1: source_type | N1: note | O1: qoq_margin_bps | P1: qoq_util_pts | Q1: wage_hike_qtr | R1: usd_inr_qavg | S1: one_off_flag
A2: Wipro | B2: Q1 FY15 | C2: 2014-06-30 | D2: 22.8 | E2: IT Services segment operating margin | F2: 77.9 | G2: 68.7 | H2: 147452 | I2: 16.1 | J2: 1740.2 | K2: 0.3 | L2: S65 | M2: Company datasheet | N2: Headcount = IT Services | Q2: =IF(COUNTIFS(Wage_Hikes!$A:$A,A2,Wage_Hikes!$D:$D,B2)>0,1,0) -> 0 | R2: =IFERROR(AVERAGEIFS(FX_USDINR!$B:$B,FX_USDINR!$C:$C,B2),"") -> 59.789133 | S2: 0
A3: Wipro | B3: Q2 FY15 | C3: 2014-09-30 | D3: 22 | E3: IT Services segment operating margin | F3: 79.4 | G3: 70 | H3: 154297 | I3: 16.5 | J3: 1771.5 | K3: 3 | L3: S65 | M3: Company datasheet | N3: Headcount = IT Services | O3: =IF(AND(TRUE(),ISNUMBER(D3),ISNUMBER(D2)),(D3-D2)*100,"") -> -80 | P3: =IF(AND(ISNUMBER(F3),ISNUMBER(F2)),F3-F2,"") -> 1.5 | Q3: =IF(COUNTIFS(Wage_Hikes!$A:$A,A3,Wage_Hikes!$D:$D,B3)>0,1,0) -> 0 | R3: =IFERROR(AVERAGEIFS(FX_USDINR!$B:$B,FX_USDINR!$C:$C,B3),"") -> 60.622333 | S3: 0
A4: Wipro | B4: Q3 FY15 | C4: 2014-12-31 | D4: 21.8 | E4: IT Services segment operating margin | F4: 78.8 | G4: 68.5 | H4: 156866 | I4: 16.5 | J4: 1795.4 | K4: 3.7 | L4: S65 | M4: Company datasheet | N4: Headcount = IT Services | O4: =IF(AND(TRUE(),ISNUMBER(D4),ISNUMBER(D3)),(D4-D3)*100,"") -> -20 | P4: =IF(AND(ISNUMBER(F4),ISNUMBER(F3)),F4-F3,"") -> -0.6 | Q4: =IF(COUNTIFS(Wage_Hikes!$A:$A,A4,Wage_Hikes!$D:$D,B4)>0,1,0) -> 0 | R4: =IFERROR(AVERAGEIFS(FX_USDINR!$B:$B,FX_USDINR!$C:$C,B4),"") -> 61.9189 | S4: 0
A5: Wipro | B5: Q4 FY15 | C5: 2015-03-31 | D5: 22 | E5: IT Services segment operating margin | F5: 80.5 | G5: 70.5 | H5: 158217 | I5: 16.5 | J5: 1774.5 | K5: 1.2 | L5: S65;S66 | M5: Company datasheet | N5: Headcount = IT Services; identical in two sheets | O5: =IF(AND(TRUE(),ISNUMBER(D5),ISNUMBER(D4)),(D5-D4)*100,"") -> 20 | P5: =IF(AND(ISNUMBER(F5),ISNUMBER(F4)),F5-F4,"") -> 1.7 | Q5: =IF(COUNTIFS(Wage_Hikes!$A:$A,A5,Wage_Hikes!$D:$D,B5)>0,1,0) -> 0 | R5: =IFERROR(AVERAGEIFS(FX_USDINR!$B:$B,FX_USDINR!$C:$C,B5),"") -> 62.200333 | S5: 0
A6: Wipro | B6: Q1 FY16 | C6: 2015-06-30 | D6: 21 | E6: IT Services segment operating margin | F6: 81.9 | G6: 71.3 | H6: 161789 | I6: 16.4 | J6: 1794.1 | K6: 0.2 | L6: S66 | M6: Company datasheet | N6: Headcount = IT Services | O6: =IF(AND(TRUE(),ISNUMBER(D6),ISNUMBER(D5)),(D6-D5)*100,"") -> -100 | P6: =IF(AND(ISNUMBER(F6),ISNUMBER(F5)),F6-F5,"") -> 1.4 | Q6: =IF(COUNTIFS(Wage_Hikes!$A:$A,A6,Wage_Hikes!$D:$D,B6)>0,1,0) -> 0 | R6: =IFERROR(AVERAGEIFS(FX_USDINR!$B:$B,FX_USDINR!$C:$C,B6),"") -> 63.3791 | S6: 0
A7: Wipro | B7: Q2 FY16 | C7: 2015-09-30 | D7: 20.7 | E7: IT Services segment operating margin | F7: 82.3 | G7: 69.5 | H7: 168396 | I7: 16.4 | J7: 1831.9 | K7: 3.1 | L7: S66 | M7: Company datasheet | N7: Headcount = IT Services | O7: =IF(AND(TRUE(),ISNUMBER(D7),ISNUMBER(D6)),(D7-D6)*100,"") -> -30 | P7: =IF(AND(ISNUMBER(F7),ISNUMBER(F6)),F7-F6,"") -> 0.4 | Q7: =IF(COUNTIFS(Wage_Hikes!$A:$A,A7,Wage_Hikes!$D:$D,B7)>0,1,0) -> 0 | R7: =IFERROR(AVERAGEIFS(FX_USDINR!$B:$B,FX_USDINR!$C:$C,B7),"") -> 64.9561 | S7: 0
A8: Wipro | B8: Q3 FY16 | C8: 2015-12-31 | D8: 20.2 | E8: IT Services segment operating margin | F8: 78 | G8: 66.4 | H8: 170664 | I8: 16.3 | J8: 1838.3 | K8: 1.4 | L8: S66 | M8: Company datasheet | N8: Headcount = IT Services | O8: =IF(AND(TRUE(),ISNUMBER(D8),ISNUMBER(D7)),(D8-D7)*100,"") -> -50 | P8: =IF(AND(ISNUMBER(F8),ISNUMBER(F7)),F8-F7,"") -> -4.3 | Q8: =IF(COUNTIFS(Wage_Hikes!$A:$A,A8,Wage_Hikes!$D:$D,B8)>0,1,0) -> 0 | R8: =IFERROR(AVERAGEIFS(FX_USDINR!$B:$B,FX_USDINR!$C:$C,B8),"") -> 65.876167 | S8: 0
A9: Wipro | B9: Q4 FY16 | C9: 2016-03-31 | D9: 20.1 | E9: IT Services segment operating margin | F9: 77.5 | G9: 68.1 | H9: 172912 | I9: 16.1 | J9: 1882 | K9: 2.7 | L9: S66 | M9: Company datasheet | N9: As originally reported; restated in S67 to margin 19.7%, headcount 156,831 (definition change) | O9: =IF(AND(TRUE(),ISNUMBER(D9),ISNUMBER(D8)),(D9-D8)*100,"") -> -10 | P9: =IF(AND(ISNUMBER(F9),ISNUMBER(F8)),F9-F8,"") -> -0.5 | Q9: =IF(COUNTIFS(Wage_Hikes!$A:$A,A9,Wage_Hikes!$D:$D,B9)>0,1,0) -> 0 | R9: =IFERROR(AVERAGEIFS(FX_USDINR!$B:$B,FX_USDINR!$C:$C,B9),"") -> 67.487867 | S9: 0
A10: Wipro | B10: Q1 FY17 | C10: 2016-06-30 | D10: 17.8 | E10: IT Services segment operating margin | F10: 79.7 | G10: 69.9 | H10: 158272 | I10: 16.5 | J10: 1930.8 | K10: 2 | L10: S67 | M10: Company datasheet | N10: Headcount basis restated from FY17 (break vs FY16) | O10: =IF(AND(TRUE(),ISNUMBER(D10),ISNUMBER(D9)),(D10-D9)*100,"") -> -230 | P10: =IF(AND(ISNUMBER(F10),ISNUMBER(F9)),F10-F9,"") -> 2.2 | Q10: =IF(COUNTIFS(Wage_Hikes!$A:$A,A10,Wage_Hikes!$D:$D,B10)>0,1,0) -> 0 | R10: =IFERROR(AVERAGEIFS(FX_USDINR!$B:$B,FX_USDINR!$C:$C,B10),"") -> 66.858967 | S10: 0
A11: Wipro | B11: Q2 FY17 | C11: 2016-09-30 | D11: 17.8 | E11: IT Services segment operating margin | F11: 82.8 | G11: 71.2 | H11: 159791 | I11: 16.6 | J11: 1916.3 | K11: 0.9 | L11: S67 | M11: Company datasheet | O11: =IF(AND(TRUE(),ISNUMBER(D11),ISNUMBER(D10)),(D11-D10)*100,"") -> 0 | P11: =IF(AND(ISNUMBER(F11),ISNUMBER(F10)),F11-F10,"") -> 3.1 | Q11: =IF(COUNTIFS(Wage_Hikes!$A:$A,A11,Wage_Hikes!$D:$D,B11)>0,1,0) -> 0 | R11: =IFERROR(AVERAGEIFS(FX_USDINR!$B:$B,FX_USDINR!$C:$C,B11),"") -> 66.9251 | S11: 0
A12: Wipro | B12: Q3 FY17 | C12: 2016-12-31 | D12: 18.3 | E12: IT Services segment operating margin | F12: 81.9 | G12: 71.6 | H12: 164176 | I12: 16.3 | J12: 1902.8 | K12: 0.6 | L12: S67 | M12: Company datasheet | O12: =IF(AND(TRUE(),ISNUMBER(D12),ISNUMBER(D11)),(D12-D11)*100,"") -> 50 | P12: =IF(AND(ISNUMBER(F12),ISNUMBER(F11)),F12-F11,"") -> -0.9 | Q12: =IF(COUNTIFS(Wage_Hikes!$A:$A,A12,Wage_Hikes!$D:$D,B12)>0,1,0) -> 0 | R12: =IFERROR(AVERAGEIFS(FX_USDINR!$B:$B,FX_USDINR!$C:$C,B12),"") -> 67.3954 | S12: 0
A13: Wipro | B13: Q4 FY17 | C13: 2017-03-31 | D13: 18.3 | E13: IT Services segment operating margin | F13: 84.8 | G13: 73.1 | H13: 165481 | I13: 16.3 | J13: 1954.6 | K13: 1.7 | L13: S67;S68 | M13: Company datasheet | N13: Identical in two sheets | O13: =IF(AND(TRUE(),ISNUMBER(D13),ISNUMBER(D12)),(D13-D12)*100,"") -> 0 | P13: =IF(AND(ISNUMBER(F13),ISNUMBER(F12)),F13-F12,"") -> 2.9 | Q13: =IF(COUNTIFS(Wage_Hikes!$A:$A,A13,Wage_Hikes!$D:$D,B13)>0,1,0) -> 0 | R13: =IFERROR(AVERAGEIFS(FX_USDINR!$B:$B,FX_USDINR!$C:$C,B13),"") -> 66.9403 | S13: 0
A14: Wipro | B14: Q1 FY18 | C14: 2017-06-30 | D14: 16.8 | E14: IT Services segment operating margin | F14: 82.1 | G14: 72 | H14: 166790 | I14: 15.9 | J14: 1971.7 | K14: 0.3 | L14: S68 | M14: Company datasheet | O14: =IF(AND(TRUE(),ISNUMBER(D14),ISNUMBER(D13)),(D14-D13)*100,"") -> -150 | P14: =IF(AND(ISNUMBER(F14),ISNUMBER(F13)),F14-F13,"") -> -2.7 | Q14: =IF(COUNTIFS(Wage_Hikes!$A:$A,A14,Wage_Hikes!$D:$D,B14)>0,1,0) -> 0 | R14: =IFERROR(AVERAGEIFS(FX_USDINR!$B:$B,FX_USDINR!$C:$C,B14),"") -> 64.4679 | S14: 0
A15: Wipro | B15: Q2 FY18 | C15: 2017-09-30 | D15: 17.3 | E15: IT Services segment operating margin | F15: 82.5 | G15: 72.9 | H15: 163759 | I15: 15.7 | J15: 2013.5 | K15: 0.3 | L15: S68 | M15: Company datasheet | O15: =IF(AND(TRUE(),ISNUMBER(D15),ISNUMBER(D14)),(D15-D14)*100,"") -> 50 | P15: =IF(AND(ISNUMBER(F15),ISNUMBER(F14)),F15-F14,"") -> 0.4 | Q15: =IF(COUNTIFS(Wage_Hikes!$A:$A,A15,Wage_Hikes!$D:$D,B15)>0,1,0) -> 0 | R15: =IFERROR(AVERAGEIFS(FX_USDINR!$B:$B,FX_USDINR!$C:$C,B15),"") -> 64.289933 | S15: 0
A16: Wipro | B16: Q3 FY18 | C16: 2017-12-31 | D16: 14.8 | E16: IT Services segment operating margin | F16: 81.9 | G16: 71 | H16: 162553 | I16: 15.9 | J16: 2013 | K16: 0.9 | L16: S68 | M16: Company datasheet | N16: One-off: customer insolvency; 17.2% normalised | O16: =IF(AND(TRUE(),ISNUMBER(D16),ISNUMBER(D15)),(D16-D15)*100,"") -> -250 | P16: =IF(AND(ISNUMBER(F16),ISNUMBER(F15)),F16-F15,"") -> -0.6 | Q16: =IF(COUNTIFS(Wage_Hikes!$A:$A,A16,Wage_Hikes!$D:$D,B16)>0,1,0) -> 0 | R16: =IFERROR(AVERAGEIFS(FX_USDINR!$B:$B,FX_USDINR!$C:$C,B16),"") -> 64.7079 | S16: 1
A17: Wipro | B17: Q4 FY18 | C17: 2018-03-31 | D17: 14.4 | E17: IT Services segment operating margin | F17: 83.4 | G17: 73.1 | H17: 163827 | I17: 16.6 | J17: 2062 | K17: 1.1 | L17: S68 | M17: Company datasheet | N17: One-offs: customer insolvency + impairment; 16.0% normalised. Restated in S69: 14.6%, headcount 159,923, revenue 2,019.1 | O17: =IF(AND(TRUE(),ISNUMBER(D17),ISNUMBER(D16)),(D17-D16)*100,"") -> -40 | P17: =IF(AND(ISNUMBER(F17),ISNUMBER(F16)),F17-F16,"") -> 1.5 | Q17: =IF(COUNTIFS(Wage_Hikes!$A:$A,A17,Wage_Hikes!$D:$D,B17)>0,1,0) -> 0 | R17: =IFERROR(AVERAGEIFS(FX_USDINR!$B:$B,FX_USDINR!$C:$C,B17),"") -> 64.373567 | S17: 1
A18: Wipro | B18: Q1 FY19 | C18: 2018-06-30 | D18: 17.6 | E18: IT Services segment operating margin | F18: 85.2 | G18: 74.5 | H18: 160846 | I18: 17.1 | J18: 1988.8 | K18: 0.2 | L18: S69 | M18: Company datasheet | N18: Utilisation excludes acquired entities | O18: =IF(AND(TRUE(),ISNUMBER(D18),ISNUMBER(D17)),(D18-D17)*100,"") -> 320 | P18: =IF(AND(ISNUMBER(F18),ISNUMBER(F17)),F18-F17,"") -> 1.8 | Q18: =IF(COUNTIFS(Wage_Hikes!$A:$A,A18,Wage_Hikes!$D:$D,B18)>0,1,0) -> 0 | R18: =IFERROR(AVERAGEIFS(FX_USDINR!$B:$B,FX_USDINR!$C:$C,B18),"") -> 66.990967 | S18: 0
A19: Wipro | B19: Q2 FY19 | C19: 2018-09-30 | D19: 15 | E19: IT Services segment operating margin | F19: 85.5 | G19: 74.4 | H19: 171451 | I19: 17.5 | J19: 2009.5 | K19: 3 | L19: S69;S70 | M19: Company datasheet | N19: One-off depresses margin; Q3 FY19 +480 bps over Q2 reported (S70) | O19: =IF(AND(TRUE(),ISNUMBER(D19),ISNUMBER(D18)),(D19-D18)*100,"") -> -260 | P19: =IF(AND(ISNUMBER(F19),ISNUMBER(F18)),F19-F18,"") -> 0.3 | Q19: =IF(COUNTIFS(Wage_Hikes!$A:$A,A19,Wage_Hikes!$D:$D,B19)>0,1,0) -> 0 | R19: =IFERROR(AVERAGEIFS(FX_USDINR!$B:$B,FX_USDINR!$C:$C,B19),"") -> 70.198767 | S19: 1
A20: Wipro | B20: Q3 FY19 | C20: 2018-12-31 | D20: 19.8 | E20: IT Services segment operating margin | F20: 83.2 | G20: 73.4 | H20: 172379 | I20: 17.9 | J20: 2046.5 | K20: 2.4 | L20: S69;S70 | M20: Company datasheet | O20: =IF(AND(TRUE(),ISNUMBER(D20),ISNUMBER(D19)),(D20-D19)*100,"") -> 480 | P20: =IF(AND(ISNUMBER(F20),ISNUMBER(F19)),F20-F19,"") -> -2.3 | Q20: =IF(COUNTIFS(Wage_Hikes!$A:$A,A20,Wage_Hikes!$D:$D,B20)>0,1,0) -> 0 | R20: =IFERROR(AVERAGEIFS(FX_USDINR!$B:$B,FX_USDINR!$C:$C,B20),"") -> 72.044 | S20: 0
A21: Wipro | B21: Q4 FY19 | C21: 2019-03-31 | D21: 19 | E21: IT Services segment operating margin | F21: 85.4 | G21: 75.4 | H21: 171425 | I21: 17.6 | J21: 2075.5 | K21: 1 | L21: S69 | M21: Company datasheet | O21: =IF(AND(TRUE(),ISNUMBER(D21),ISNUMBER(D20)),(D21-D20)*100,"") -> -80 | P21: =IF(AND(ISNUMBER(F21),ISNUMBER(F20)),F21-F20,"") -> 2.2 | Q21: =IF(COUNTIFS(Wage_Hikes!$A:$A,A21,Wage_Hikes!$D:$D,B21)>0,1,0) -> 0 | R21: =IFERROR(AVERAGEIFS(FX_USDINR!$B:$B,FX_USDINR!$C:$C,B21),"") -> 70.4578 | S21: 0
A22: Wipro | B22: Q1 FY20 | C22: 2019-06-30 | D22: 18.4 | E22: IT Services segment operating margin | F22: 85 | G22: 73.9 | H22: 174850 | I22: 17.6 | J22: 2038.8 | K22: -0.7 | L22: S08 | M22: Company datasheet | O22: =IF(AND(TRUE(),ISNUMBER(D22),ISNUMBER(D21)),(D22-D21)*100,"") -> -60 | P22: =IF(AND(ISNUMBER(F22),ISNUMBER(F21)),F22-F21,"") -> -0.4 | Q22: =IF(COUNTIFS(Wage_Hikes!$A:$A,A22,Wage_Hikes!$D:$D,B22)>0,1,0) -> 0 | R22: =IFERROR(AVERAGEIFS(FX_USDINR!$B:$B,FX_USDINR!$C:$C,B22),"") -> 69.525833 | S22: 0
A23: Wipro | B23: Q2 FY20 | C23: 2019-09-30 | D23: 18.1 | E23: IT Services segment operating margin | F23: 82.1 | G23: 71.4 | H23: 181453 | I23: 17 | J23: 2048.9 | K23: 1.1 | L23: S08 | M23: Company datasheet | O23: =IF(AND(TRUE(),ISNUMBER(D23),ISNUMBER(D22)),(D23-D22)*100,"") -> -30 | P23: =IF(AND(ISNUMBER(F23),ISNUMBER(F22)),F23-F22,"") -> -2.9 | Q23: =IF(COUNTIFS(Wage_Hikes!$A:$A,A23,Wage_Hikes!$D:$D,B23)>0,1,0) -> 0 | R23: =IFERROR(AVERAGEIFS(FX_USDINR!$B:$B,FX_USDINR!$C:$C,B23),"") -> 70.413067 | S23: 0
A24: Wipro | B24: Q3 FY20 | C24: 2019-12-31 | D24: 18.4 | E24: IT Services segment operating margin | F24: 79.6 | G24: 70.2 | H24: 187318 | I24: 15.7 | J24: 2094.8 | K24: 1.8 | L24: S08 | M24: Company datasheet | O24: =IF(AND(TRUE(),ISNUMBER(D24),ISNUMBER(D23)),(D24-D23)*100,"") -> 30 | P24: =IF(AND(ISNUMBER(F24),ISNUMBER(F23)),F24-F23,"") -> -2.5 | Q24: =IF(COUNTIFS(Wage_Hikes!$A:$A,A24,Wage_Hikes!$D:$D,B24)>0,1,0) -> 0 | R24: =IFERROR(AVERAGEIFS(FX_USDINR!$B:$B,FX_USDINR!$C:$C,B24),"") -> 71.219833 | S24: 0
A25: Wipro | B25: Q4 FY20 | C25: 2020-03-31 | D25: 17.6 | E25: IT Services segment operating margin | F25: 82.6 | G25: 73.4 | H25: 182886 | I25: 14.7 | J25: 2073.7 | K25: 0.4 | L25: S08 | M25: Company datasheet | O25: =IF(AND(TRUE(),ISNUMBER(D25),ISNUMBER(D24)),(D25-D24)*100,"") -> -80 | P25: =IF(AND(ISNUMBER(F25),ISNUMBER(F24)),F25-F24,"") -> 3 | Q25: =IF(COUNTIFS(Wage_Hikes!$A:$A,A25,Wage_Hikes!$D:$D,B25)>0,1,0) -> 0 | R25: =IFERROR(AVERAGEIFS(FX_USDINR!$B:$B,FX_USDINR!$C:$C,B25),"") -> 72.452233 | S25: 0
A26: Wipro | B26: Q1 FY21 | C26: 2020-06-30 | D26: 19 | E26: IT Services segment operating margin | F26: 84.5 | G26: 75 | H26: 181804 | I26: 13 | J26: 1921.6 | K26: -7.5 | L26: S08 | M26: Company datasheet | N26: COVID quarter | O26: =IF(AND(TRUE(),ISNUMBER(D26),ISNUMBER(D25)),(D26-D25)*100,"") -> 140 | P26: =IF(AND(ISNUMBER(F26),ISNUMBER(F25)),F26-F25,"") -> 1.9 | Q26: =IF(COUNTIFS(Wage_Hikes!$A:$A,A26,Wage_Hikes!$D:$D,B26)>0,1,0) -> 0 | R26: =IFERROR(AVERAGEIFS(FX_USDINR!$B:$B,FX_USDINR!$C:$C,B26),"") -> 75.844467 | S26: 1
A27: Wipro | B27: Q2 FY21 | C27: 2020-09-30 | D27: 19.2 | E27: IT Services segment operating margin | F27: 86.9 | G27: 76.4 | H27: 185243 | I27: 11 | J27: 1992.4 | K27: 2 | L27: S08 | M27: Company datasheet | O27: =IF(AND(TRUE(),ISNUMBER(D27),ISNUMBER(D26)),(D27-D26)*100,"") -> 20 | P27: =IF(AND(ISNUMBER(F27),ISNUMBER(F26)),F27-F26,"") -> 2.4 | Q27: =IF(COUNTIFS(Wage_Hikes!$A:$A,A27,Wage_Hikes!$D:$D,B27)>0,1,0) -> 0 | R27: =IFERROR(AVERAGEIFS(FX_USDINR!$B:$B,FX_USDINR!$C:$C,B27),"") -> 74.3392 | S27: 0
A28: Wipro | B28: Q3 FY21 | C28: 2020-12-31 | D28: 21.7 | E28: IT Services segment operating margin | F28: 86.3 | G28: 74.8 | H28: 190308 | I28: 11 | J28: 2071 | K28: 3.4 | L28: S07 | M28: Company datasheet | O28: =IF(AND(TRUE(),ISNUMBER(D28),ISNUMBER(D27)),(D28-D27)*100,"") -> 250 | P28: =IF(AND(ISNUMBER(F28),ISNUMBER(F27)),F28-F27,"") -> -0.6 | Q28: =IF(COUNTIFS(Wage_Hikes!$A:$A,A28,Wage_Hikes!$D:$D,B28)>0,1,0) -> 0 | R28: =IFERROR(AVERAGEIFS(FX_USDINR!$B:$B,FX_USDINR!$C:$C,B28),"") -> 73.805133 | S28: 0
A29: Wipro | B29: Q4 FY21 | C29: 2021-03-31 | D29: 21 | E29: IT Services segment operating margin | F29: 86 | G29: 76.7 | H29: 197712 | I29: 12.1 | J29: 2152.4 | K29: 3 | L29: S06 | M29: Company datasheet | O29: =IF(AND(TRUE(),ISNUMBER(D29),ISNUMBER(D28)),(D29-D28)*100,"") -> -70 | P29: =IF(AND(ISNUMBER(F29),ISNUMBER(F28)),F29-F28,"") -> -0.3 | Q29: =IF(COUNTIFS(Wage_Hikes!$A:$A,A29,Wage_Hikes!$D:$D,B29)>0,1,0) -> 1 | R29: =IFERROR(AVERAGEIFS(FX_USDINR!$B:$B,FX_USDINR!$C:$C,B29),"") -> 72.911833 | S29: 0
A30: Wipro | B30: Q1 FY22 | C30: 2021-06-30 | D30: 18.8 | E30: IT Services segment operating margin | F30: 86.8 | G30: 77.7 | H30: 209890 | I30: 15.5 | J30: 2414.5 | K30: 12 | L30: S06 | M30: Company datasheet | N30: Capco acquisition consolidated | O30: =IF(AND(TRUE(),ISNUMBER(D30),ISNUMBER(D29)),(D30-D29)*100,"") -> -220 | P30: =IF(AND(ISNUMBER(F30),ISNUMBER(F29)),F30-F29,"") -> 0.8 | Q30: =IF(COUNTIFS(Wage_Hikes!$A:$A,A30,Wage_Hikes!$D:$D,B30)>0,1,0) -> 1 | R30: =IFERROR(AVERAGEIFS(FX_USDINR!$B:$B,FX_USDINR!$C:$C,B30),"") -> 73.767767 | S30: 0
A31: Wipro | B31: Q2 FY22 | C31: 2021-09-30 | D31: 17.8 | E31: IT Services segment operating margin | F31: 89.2 | G31: 78.1 | H31: 221365 | I31: 20.5 | J31: 2580 | K31: 8.1 | L31: S06 | M31: Company datasheet | O31: =IF(AND(TRUE(),ISNUMBER(D31),ISNUMBER(D30)),(D31-D30)*100,"") -> -100 | P31: =IF(AND(ISNUMBER(F31),ISNUMBER(F30)),F31-F30,"") -> 2.4 | Q31: =IF(COUNTIFS(Wage_Hikes!$A:$A,A31,Wage_Hikes!$D:$D,B31)>0,1,0) -> 1 | R31: =IFERROR(AVERAGEIFS(FX_USDINR!$B:$B,FX_USDINR!$C:$C,B31),"") -> 74.096733 | S31: 0
A32: Wipro | B32: Q3 FY22 | C32: 2021-12-31 | D32: 17.6 | E32: IT Services segment operating margin | F32: 85.8 | G32: 75.6 | H32: 231671 | I32: 22.7 | J32: 2639.7 | K32: 3 | L32: S06 | M32: Company datasheet | O32: =IF(AND(TRUE(),ISNUMBER(D32),ISNUMBER(D31)),(D32-D31)*100,"") -> -20 | P32: =IF(AND(ISNUMBER(F32),ISNUMBER(F31)),F32-F31,"") -> -3.4 | Q32: =IF(COUNTIFS(Wage_Hikes!$A:$A,A32,Wage_Hikes!$D:$D,B32)>0,1,0) -> 0 | R32: =IFERROR(AVERAGEIFS(FX_USDINR!$B:$B,FX_USDINR!$C:$C,B32),"") -> 74.9306 | S32: 0
A33: Wipro | B33: Q4 FY22 | C33: 2022-03-31 | D33: 17 | E33: IT Services segment operating margin | F33: 85.2 | G33: 75.8 | H33: 243128 | I33: 23.8 | J33: 2721.7 | K33: 3.1 | L33: S06 | M33: Company datasheet | O33: =IF(AND(TRUE(),ISNUMBER(D33),ISNUMBER(D32)),(D33-D32)*100,"") -> -60 | P33: =IF(AND(ISNUMBER(F33),ISNUMBER(F32)),F33-F32,"") -> -0.6 | Q33: =IF(COUNTIFS(Wage_Hikes!$A:$A,A33,Wage_Hikes!$D:$D,B33)>0,1,0) -> 0 | R33: =IFERROR(AVERAGEIFS(FX_USDINR!$B:$B,FX_USDINR!$C:$C,B33),"") -> 75.188867 | S33: 0
A34: Wipro | B34: Q1 FY23 | C34: 2022-06-30 | D34: 14.9 | E34: IT Services segment operating margin | F34: 83.8 | H34: 262049 | I34: 23 | J34: 2756.1 | K34: 1.9 | L34: S05 | M34: Company datasheet | O34: =IF(AND(TRUE(),ISNUMBER(D34),ISNUMBER(D33)),(D34-D33)*100,"") -> -210 | P34: =IF(AND(ISNUMBER(F34),ISNUMBER(F33)),F34-F33,"") -> -1.4 | Q34: =IF(COUNTIFS(Wage_Hikes!$A:$A,A34,Wage_Hikes!$D:$D,B34)>0,1,0) -> 0 | R34: =IFERROR(AVERAGEIFS(FX_USDINR!$B:$B,FX_USDINR!$C:$C,B34),"") -> 77.185067 | S34: 0
A35: Wipro | B35: Q2 FY23 | C35: 2022-09-30 | D35: 15.1 | E35: IT Services segment operating margin | F35: 79.8 | H35: 262626 | I35: 22.9 | J35: 2817.4 | K35: 4.1 | L35: S05 | M35: Company datasheet | O35: =IF(AND(TRUE(),ISNUMBER(D35),ISNUMBER(D34)),(D35-D34)*100,"") -> 20 | P35: =IF(AND(ISNUMBER(F35),ISNUMBER(F34)),F35-F34,"") -> -4 | Q35: =IF(COUNTIFS(Wage_Hikes!$A:$A,A35,Wage_Hikes!$D:$D,B35)>0,1,0) -> 1 | R35: =IFERROR(AVERAGEIFS(FX_USDINR!$B:$B,FX_USDINR!$C:$C,B35),"") -> 79.783933 | S35: 0
A36: Wipro | B36: Q3 FY23 | C36: 2022-12-31 | D36: 16.2 | E36: IT Services segment operating margin | F36: 79.7 | H36: 262109 | I36: 21.2 | J36: 2821.4 | K36: 0.6 | L36: S05 | M36: Company datasheet | N36: Value from FY24 datasheet; check original Q3 FY23 datasheet for restatement | O36: =IF(AND(TRUE(),ISNUMBER(D36),ISNUMBER(D35)),(D36-D35)*100,"") -> 110 | P36: =IF(AND(ISNUMBER(F36),ISNUMBER(F35)),F36-F35,"") -> -0.1 | Q36: =IF(COUNTIFS(Wage_Hikes!$A:$A,A36,Wage_Hikes!$D:$D,B36)>0,1,0) -> 0 | R36: =IFERROR(AVERAGEIFS(FX_USDINR!$B:$B,FX_USDINR!$C:$C,B36),"") -> 82.1486 | S36: 0
A37: Wipro | B37: Q4 FY23 | C37: 2023-03-31 | D37: 16.3 | E37: IT Services segment operating margin | F37: 81.7 | H37: 258570 | I37: 19.4 | J37: 2839.5 | K37: -0.7 | L37: S05 | M37: Company datasheet | O37: =IF(AND(TRUE(),ISNUMBER(D37),ISNUMBER(D36)),(D37-D36)*100,"") -> 10 | P37: =IF(AND(ISNUMBER(F37),ISNUMBER(F36)),F37-F36,"") -> 2 | Q37: =IF(COUNTIFS(Wage_Hikes!$A:$A,A37,Wage_Hikes!$D:$D,B37)>0,1,0) -> 0 | R37: =IFERROR(AVERAGEIFS(FX_USDINR!$B:$B,FX_USDINR!$C:$C,B37),"") -> 82.202333 | S37: 0
A38: Wipro | B38: Q1 FY24 | C38: 2023-06-30 | D38: 16 | E38: IT Services segment operating margin | F38: 83.7 | H38: 249758 | I38: 17.3 | J38: 2778.5 | K38: -2.8 | L38: S05 | M38: Company datasheet | O38: =IF(AND(TRUE(),ISNUMBER(D38),ISNUMBER(D37)),(D38-D37)*100,"") -> -30 | P38: =IF(AND(ISNUMBER(F38),ISNUMBER(F37)),F38-F37,"") -> 2 | Q38: =IF(COUNTIFS(Wage_Hikes!$A:$A,A38,Wage_Hikes!$D:$D,B38)>0,1,0) -> 0 | R38: =IFERROR(AVERAGEIFS(FX_USDINR!$B:$B,FX_USDINR!$C:$C,B38),"") -> 82.1638 | S38: 0
A39: Wipro | B39: Q2 FY24 | C39: 2023-09-30 | D39: 16.1 | E39: IT Services segment operating margin | F39: 84.5 | H39: 244707 | I39: 15.5 | J39: 2713.3 | K39: -2 | L39: S05;S04 | M39: Company datasheet | O39: =IF(AND(TRUE(),ISNUMBER(D39),ISNUMBER(D38)),(D39-D38)*100,"") -> 10 | P39: =IF(AND(ISNUMBER(F39),ISNUMBER(F38)),F39-F38,"") -> 0.8 | Q39: =IF(COUNTIFS(Wage_Hikes!$A:$A,A39,Wage_Hikes!$D:$D,B39)>0,1,0) -> 0 | R39: =IFERROR(AVERAGEIFS(FX_USDINR!$B:$B,FX_USDINR!$C:$C,B39),"") -> 82.679567 | S39: 0
A40: Wipro | B40: Q3 FY24 | C40: 2023-12-31 | D40: 16 | E40: IT Services segment operating margin | F40: 84 | H40: 240234 | I40: 14.2 | J40: 2656.1 | K40: -1.7 | L40: S04 | M40: Company datasheet | O40: =IF(AND(TRUE(),ISNUMBER(D40),ISNUMBER(D39)),(D40-D39)*100,"") -> -10 | P40: =IF(AND(ISNUMBER(F40),ISNUMBER(F39)),F40-F39,"") -> -0.5 | Q40: =IF(COUNTIFS(Wage_Hikes!$A:$A,A40,Wage_Hikes!$D:$D,B40)>0,1,0) -> 1 | R40: =IFERROR(AVERAGEIFS(FX_USDINR!$B:$B,FX_USDINR!$C:$C,B40),"") -> 83.2454 | S40: 0
...

Sheet Wage_Hikes
A1: Quarter in which each salary hike first hits the P&L. Wipro and Infosys FY15–FY20 and TCS FY22–FY24 cycles not yet sourced (DQ19). Quarterly_Panel column Q flags these quarters by formula.
A3: firm | B3: hike_cycle | C3: effective_date | D3: first_quarter_of_impact | E3: scope | F3: source_id | G3: note
A4: Wipro | B4: FY21 | C4: 2021-01-01 | D4: Q4 FY21 | E4: Bands B3 and below | F4: S96 | G4: Referenced as 'previously announced for these bands in January 2021'
A5: Wipro | B5: FY22 | C5: 2021-06-01 | D5: Q1 FY22 | E5: Manager level and above | F5: S96
A6: Wipro | B6: FY22 | C6: 2021-09-01 | D6: Q2 FY22 | E6: Bands B3 and below (about 80% of workforce) | F6: S96 | G6: Second hike in 2021
A7: Wipro | B7: FY23 | C7: 2022-09-01 | D7: Q2 FY23 | E7: Broad | F7: S95 | G7: CFO: 'last salary increase in September of last year' (said July 2023); day not stated
A8: Wipro | B8: FY24 | C8: 2023-12-01 | D8: Q3 FY24 | E8: Eligible employees | F8: S93 | G8: Originally due September 2023
A9: Wipro | B9: FY25 | C9: 2024-09-01 | D9: Q2 FY25 | E9: Eligible employees | F9: S92
A10: Wipro | B10: FY26 | C10: 2026-03-01 | D10: Q4 FY26 | E10: Eligible employees (merit salary increase) | F10: S94 | G10: First hike in 18 months; full-quarter effect from Q1 FY27
A11: Infosys | B11: FY21 | C11: 2021-01-01 | D11: Q4 FY21 | E11: All employees | F11: S104
A12: Infosys | B12: FY23 | C12: 2022-04-01 | D12: Q1 FY23 | E12: Broad | F12: S16 | G12: Date inferred from CFO margin walk ('1.6% due to salary increases' in Q1 FY23); exact day not stated
A13: Infosys | B13: FY24 | C13: 2023-11-01 | D13: Q3 FY24 | E13: Broad | F13: S103 | G13: 'last raised its salaries in November 2023'
A14: Infosys | B14: FY25 | C14: 2025-01-01 | D14: Q4 FY25 | E14: Phase 1 | F14: S102;S103
A15: Infosys | B15: FY25 | C15: 2025-04-01 | D15: Q1 FY26 | E15: Phase 2 | F15: S102 | G15: CFO; Q1 FY26 walk shows −100 bps compensation (S20)
A16: Infosys | B16: FY27 | C16: 2026-10-01 | D16: Q3 FY27 | E16: Most employees | F16: S101 | G16: After panel end
A17: Infosys | B17: FY27 | C17: 2027-01-01 | D17: Q4 FY27 | E17: Senior employees | F17: S101 | G17: After panel end
A18: TCS | B18: FY25 | C18: 2024-04-01 | D18: Q1 FY25 | E18: Broad | F18: S99
A19: TCS | B19: FY26 | C19: 2025-09-01 | D19: Q2 FY26 | E19: About 80% of workforce | F19: S97;S100;S84 | G19: Deferred from April; CFO: one month of impact in Q2, full quarter in Q3
A20: TCS | B20: FY27 | C20: 2026-04-01 | D20: Q1 FY27 | E20: All eligible employees | F20: S98;S100;S85 | G20: CFO: 170 bps margin impact

Sheet FX_USDINR
A1: Source S91: US Federal Reserve G.5 (via FRED, series EXINUS) — monthly average of daily noon buying rates in New York, rupees per US dollar. Quarterly averages are computed in Quarterly_Panel column R (AVERAGEIFS).
A3: month | B3: usd_inr_monthly_avg | C3: fiscal_quarter
A4: 2014-01-01 | B4: 62.1057 | C4: Q4 FY14
A5: 2014-02-01 | B5: 62.1642 | C5: Q4 FY14
A6: 2014-03-01 | B6: 60.9476 | C6: Q4 FY14
A7: 2014-04-01 | B7: 60.3464 | C7: Q1 FY15
A8: 2014-05-01 | B8: 59.2843 | C8: Q1 FY15
A9: 2014-06-01 | B9: 59.7367 | C9: Q1 FY15
A10: 2014-07-01 | B10: 60.0956 | C10: Q2 FY15
A11: 2014-08-01 | B11: 60.8738 | C11: Q2 FY15
A12: 2014-09-01 | B12: 60.8976 | C12: Q2 FY15
A13: 2014-10-01 | B13: 61.3668 | C13: Q3 FY15
A14: 2014-11-01 | B14: 61.6828 | C14: Q3 FY15
A15: 2014-12-01 | B15: 62.7071 | C15: Q3 FY15
... A156: 2026-09-01 | B156: 95.5124 | C156: Q2 FY27

Sheet TCS_Commentary
A1: TCS does not publish utilisation. This log records what management said about utilisation, bench and capacity each quarter, coded only as stated (no inference).
A3: quarter | B3: call_date | C3: topic | D3: statement (quoted) | E3: speaker | F3: source_id | G3: coded_direction | H3: policy_period
A4: Q4 FY25 | B4: 2025-04-10 | C4: Utilisation | D4: "we focused on improving utilization, productivity and realization" (not quantified) | E4: Samir Seksaria (CFO) | F4: S23 | G4: Lever named | H4: Pre-policy
A5: Q1 FY26 | B5: 2025-07-10 | C5: Utilisation | D5: "The demand contraction during the quarter had an impact on our utilization" | E5: Samir Seksaria (CFO) | F5: S105 | G5: Utilisation down | H5: Policy quarter (cap from 12 Jun 2025)
A6: Q1 FY26 | B6: 2025-07-10 | C6: Capacity | D6: "leads to us carrying excess capacity or additional capacity" | E6: Samir Seksaria (CFO) | F6: S105 | G6: Excess capacity | H6: Policy quarter
A7: Q2 FY26 | B7: 2025-10-09 | C7: Bench | D7: "there has been involuntary attrition as part of regular ongoing efforts pertaining to performance and bench policies" | E7: Sudeep Kunnumal (CHRO) | F7: S84 | G7: Bench enforcement | H7: Post-policy
A8: Q2 FY26 | B8: 2025-10-09 | C8: Restructuring | D8: "We have released 1% of our workforce, mainly mid and senior level"; ₹1,135 crore severance | E8: Sudeep Kunnumal (CHRO) | F8: S84 | G8: Headcount cut | H8: Confounder for the before/after test
A9: Q2 FY26 | B9: 2025-10-09 | C9: Margin | D9: Pyramid rebalancing +40 bps, operating efficiency +20 bps | E9: Samir Seksaria (CFO) | F9: S84 | G9: Efficiency up | H9: Post-policy
A10: Q3 FY26 | B10: 2026-01-12 | C10: Restructuring | D10: "in this quarter, we released approximately 1,800 people" | E10: Sudeep Kunnumal (CHRO) | F10: S106 | G10: Headcount cut | H10: Post-policy
A11: Q3 FY26 | B11: 2026-01-12 | C11: Margin | D11: Productivity, pyramid and other operational efficiencies +80 bps | E11: Samir Seksaria (CFO) | F11: S106 | G11: Efficiency up | H11: Post-policy
A12: Q4 FY26 | B12: 2026-04-09 | C12: Capacity | D12: "higher external consultants' cost of 40 basis points" | E12: Samir Seksaria (CFO) | F12: S107 | G12: External capacity up | H12: Post-policy
A13: Q1 FY27 | B13: 2026-07-09 | C13: Utilisation | D13: Not discussed; wage increments −170 bps | E13: Samir Seksaria (CFO) | F13: S85 | G13: Not stated | H13: Post-policy
A14: Q2 FY27 | B14: 2026-10-08 | C14: Bench | D14: "we have invested in a higher bench and increased hiring of subcontractors" | E14: Samir Seksaria (CFO) | F14: S86 | G14: Bench up | H14: Post-policy: reversal
A15: Q2 FY27 | B15: 2026-10-08 | C15: Utilisation | D15: "driving better productivity and driving better utilization would be on our radar" | E15: Samir Seksaria (CFO) | F15: S86 | G15: Lever named | H15: Post-policy

Sheet Margin_Walks
A1: walk_id | B1: firm | C1: quarter | D1: total_margin_change_bps | E1: util_attributed_bps | F1: tier | G1: util_level_after_pct | H1: util_change_pts | I1: bps_per_util_point | J1: driver_wording (quoted) | K1: speaker | L1: source_id | M1: note
A2: MW01 | B2: Infosys | C2: Q1 FY23 | D2: -150 | E2: -40 | F2: A | G2: 84.7 | H2: -2.3 | I2: =IF(AND(ISNUMBER(E2),ISNUMBER(H2),H2<>0),E2/H2,"") -> 17.391304 | J2: "0.4% due to drop in utilization as we create capacity for future"; "40 basis points because of utilization on margins" | K2: Nilanjan Roy (CFO) | L2: S16;S42 | M2: Utilisation excl. trainees 87.0% -> 84.7% (fact sheet S42)
A3: MW02 | B3: HCLTech | C3: Q1 FY26 | D3: -161 | E3: -80 | F3: A | I3: =IF(AND(ISNUMBER(E3),ISNUMBER(H3),H3<>0),E3/H3,"") | J3: "Lower utilization due to specialized hiring and skill/location mismatch: 80 bps" | K3: Management, via broker note | L3: S25;S33 | M3: HCLTech does not publish utilisation, so bps per point cannot be computed
A4: MW03 | B4: Infosys | C4: Q2 FY21 | E4: 80 | F4: A | G4: 83.6 | H4: 2.4 | I4: =IF(AND(ISNUMBER(E4),ISNUMBER(H4),H4<>0),E4/H4,"") -> 33.333333 | J4: 80 bps of margin gain attributed to a 2.4% increase in utilisation (as recorded in D1) | K4: Infosys management | L4: S32;S72 | M4: Quarter confirmed: fact sheet S72 shows utilisation 81.2% → 83.6% (+2.4 pts) and margin 22.7% → 25.4%
A5: MW04 | B5: Infosys | C5: Q3 FY21 | E5: 100 | F5: B | G5: 86.3 | I5: =IF(AND(ISNUMBER(E5),ISNUMBER(H5),H5<>0),E5/H5,"") | J5: "a 100-basis points improvement due to better operating parameters like utilization, on-site mix and other cost levers" | K5: Nilanjan Roy (CFO) | L5: S17 | M5: Bundled: utilisation + onsite mix + other levers
A6: MW05 | B6: Infosys | C6: Q3 FY23 | D6: 0 | E6: -80 | F6: B | G6: 81.7 | H6: -1.9 | I6: =IF(AND(ISNUMBER(E6),ISNUMBER(H6),H6<>0),E6/H6,"") -> 42.105263 | J6: "80 basis points due to seasonal weakness in operating parameters, higher third-party costs, furloughs" | K6: Nilanjan Roy (CFO) | L6: S21 | M6: Bundled; utilisation fell to 81.7% excl. trainees
A7: MW06 | B7: Infosys | C7: Q2 FY24 | D7: 40 | E7: 50 | F7: B | G7: 81.8 | H7: 0.7 | I7: =IF(AND(ISNUMBER(E7),ISNUMBER(H7),H7<>0),E7/H7,"") -> 71.428571 | J7: "0.5% from cost optimization benefits" ... "comprising of higher utilization, pricing, etc." | K7: Nilanjan Roy (CFO) | L7: S22 | M7: Bundled: utilisation + pricing
A8: MW07 | B8: Wipro | C8: Q1 FY21 | D8: 140 | E8: 100 | F8: B | I8: =IF(AND(ISNUMBER(E8),ISNUMBER(H8),H8<>0),E8/H8,"") | J8: "the operation, which is nearly 1%" ... "you've seen utilization improving, you've seen offshore rate improving" | K8: Jatin Dalal (CFO) | L8: S24 | M8: Bundled; auto-generated transcript; components do not reconcile
A9: MW08 | B9: HCLTech | C9: Q2 FY24 | D9: 154 | F9: B | I9: =IF(AND(ISNUMBER(E9),ISNUMBER(H9),H9<>0),E9/H9,"") | J9: "EBIT margin improved 154 basis points sequentially to 18.5%, driven by productivity, utilization, and cost optimization" | K9: Call summary | L9: S27 | M9: Total only; no split by driver
A10: MW09 | B10: Infosys | C10: Q1 FY27 | F10: C | G10: 84.9 | H10: 1.9 | I10: =IF(AND(ISNUMBER(E10),ISNUMBER(H10),H10<>0),E10/H10,"") | J10: "utilization, excluding trainees, improving by 1.9% to 84.9%"; walk lists currency +70, Maximus +20, AI investment -50 bps | K10: Jayesh Sanghrajka (CFO) | L10: S14 | M10: Utilisation not given its own bps
A11: MW10 | B11: Infosys | C11: Q1 FY26 | D11: -20 | F11: C | G11: 85.2 | H11: 0.3 | I11: =IF(AND(ISNUMBER(E11),ISNUMBER(H11),H11<>0),E11/H11,"") | J11: "70 basis points from increase in realization due to Maximus and seasonality" | K11: Jayesh Sanghrajka (CFO) | L11: S20 | M11: Utilisation inside Project Maximus
A12: MW11 | B12: Infosys | C12: Q2 FY25 | D12: 0 | F12: C | G12: 85.9 | H12: 0.6 | I12: =IF(AND(ISNUMBER(E12),ISNUMBER(H12),H12<>0),E12/H12,"") | J12: "80 basis points benefit from Project Maximus" | K12: Jayesh Sanghrajka (CFO) | L12: S19 | M12: Utilisation inside Project Maximus
A13: MW12 | B13: Infosys | C13: Q3 FY25 | F13: C | G13: 86 | I13: =IF(AND(ISNUMBER(E13),ISNUMBER(H13),H13<>0),E13/H13,"") | J13: "30 bps from Project Maximus"; "86% is a little bit above our comfort level" | K13: Jayesh Sanghrajka (CFO) | L13: S18
A14: MW13 | B14: Infosys | C14: Q4 FY25 | F14: C | G14: 84.9 | I14: =IF(AND(ISNUMBER(E14),ISNUMBER(H14),H14<>0),E14/H14,"") | J14: "30 basis points from Maximus"; compensation -140 bps | K14: Jayesh Sanghrajka (CFO) | L14: S15
A15: MW14 | B15: TCS | C15: Q4 FY25 | D15: -30 | F15: C | I15: =IF(AND(ISNUMBER(E15),ISNUMBER(H15),H15<>0),E15/H15,"") | J15: "we focused on improving utilization, productivity and realization" (not quantified) | K15: Samir Seksaria (CFO) | L15: S23 | M15: Named drivers net -120 bps vs reported -30 bps
A16: MW15 | B16: Tech Mahindra | C16: Q1 FY26 | D16: 60 | F16: C | I16: =IF(AND(ISNUMBER(E16),ISNUMBER(H16),H16<>0),E16/H16,"") | J16: "Headwinds on margin came from ... lower utilization" (not quantified) | K16: Broker note | L16: S28 | M16: Utilisation incl. trainees 85.1%
A17: MW16 | B17: HCLTech | C17: FY26 guidance | F17: C | I17: =IF(AND(ISNUMBER(E17),ISNUMBER(H17),H17<>0),E17/H17,"") | J17: "lower Utilization ... to cost 10-20 bps" (forward-looking guidance) | K17: Management, via broker note | L17: S25 | M17: Guidance, not an outcome; exclude from estimation
A18: MW17 | B18: Infosys | C18: Q1 FY20 | D18: -100 | E18: 70 | F18: A | G18: 83.1 | H18: 0.8 | I18: =IF(AND(ISNUMBER(E18),ISNUMBER(H18),H18<>0),E18/H18,"") -> 87.5 | J18: "increases in utilization, which helped margins by 70 basis points" | K18: Nilanjan Roy (CFO) | L18: S74;S73 | M18: Utilisation 82.3% (S73) → 83.1%; CFO said 'up nearly 70 basis points'
A19: MW18 | B19: Infosys | C19: Q2 FY19 (year-on-year) | E19: 40 | F19: A | G19: 85.6 | I19: =IF(AND(ISNUMBER(E19),ISNUMBER(H19),H19<>0),E19/H19,"") | J19: "higher utilization of 40 basis points" (year-on-year reconciliation) | K19: M.D. Ranganath (CFO) | L19: S77 | M19: Year-on-year, not sequential; Q2 FY18 utilisation needed to compute bps per point
A20: MW19 | B20: Infosys | C20: Q3 FY19 | D20: -110 | E20: -80 | F20: B | G20: 83.8 | H20: -1.8 | I20: =IF(AND(ISNUMBER(E20),ISNUMBER(H20),H20<>0),E20/H20,"") -> 44.444444 | J20: "drop in utilization and higher onsite mix impacted operating margin by 80 basis points" | K20: Jayesh Sanghrajka (CFO) | L20: S78 | M20: Bundled with onsite mix; utilisation 85.6% → 83.8% (furloughs)
A21: MW20 | B21: Infosys | C21: Q4 FY18 | D21: 40 | F21: B | G21: 84.7 | I21: =IF(AND(ISNUMBER(E21),ISNUMBER(H21),H21<>0),E21/H21,"") | J21: "Currency movement helped the margins by 20 basis points which was fully offset by drop in utilization and price realization" | K21: M.D. Ranganath (CFO) | L21: S76 | M21: Utilisation + pricing about −20 bps combined; not separable
A22: MW21 | B22: Infosys | C22: Q2 FY20 | D22: 120 | E22: 110 | F22: B | G22: 84.9 | H22: 1.8 | I22: =IF(AND(ISNUMBER(E22),ISNUMBER(H22),H22<>0),E22/H22,"") -> 61.111111 | J22: "Higher utilization, lower onsite mix and other cost optimization measures helped operating margins by 110 basis points" | K22: Nilanjan Roy (CFO) | L22: S79 | M22: Bundled; utilisation +1.8 pts per COO
A23: MW22 | B23: Tech Mahindra | C23: Q3 FY19 | D23: 50 | E23: 40 | F23: A | I23: =IF(AND(ISNUMBER(E23),ISNUMBER(H23),H23<>0),E23/H23,"") | J23: "also about utilization which was helping to the tune of about 40 basis" | K23: Manoj Bhat (CFO) | L23: S80 | M23: Utilisation change not stated; needs TechM Q2–Q3 FY19 fact sheets
A24: MW23 | B24: Tech Mahindra | C24: Q3 FY16 | D24: 30 | F24: C | I24: =IF(AND(ISNUMBER(E24),ISNUMBER(H24),H24<>0),E24/H24,"") | J24: "The margin tailwinds came from cost optimization program, improved utilization, lower SG&A" | K24: Milind Kulkarni (CFO) | L24: S83 | M24: EBITDA margin basis
A25: MW24 | B25: TCS | C25: Q2 FY26 | D25: 70 | F25: C | I25: =IF(AND(ISNUMBER(E25),ISNUMBER(H25),H25<>0),E25/H25,"") | J25: Currency +80, wage hike and QVA −70, pyramid rebalancing +40, operating efficiency +20 bps; excl. one-time severance | K25: Samir Seksaria (CFO) | L25: S84 | M25: First full quarter after the 35-day bench cap; utilisation not named
A26: MW25 | B26: TCS | C26: Q1 FY27 | D26: -130 | F26: C | I26: =IF(AND(ISNUMBER(E26),ISNUMBER(H26),H26<>0),E26/H26,"") | J26: "annual increments ... impacted margins by 170 bps"; currency and efficiency +40 bps | K26: Samir Seksaria (CFO) | L26: S85 | M26: Wage-hike quarter
A27: MW26 | B27: TCS | C27: Q2 FY27 | D27: 0 | F27: C | I27: =IF(AND(ISNUMBER(E27),ISNUMBER(H27),H27<>0),E27/H27,"") | J27: "we have invested in a higher bench and increased hiring of subcontractors"; utilisation named as a lever | K27: Samir Seksaria (CFO) | L27: S86 | M27: Bench rebuilt after the 2025 policy
A28: MW27 | B28: TCS | C28: Q3 FY26 | D28: 0 | F28: C | I28: =IF(AND(ISNUMBER(E28),ISNUMBER(H28),H28<>0),E28/H28,"") | J28: Productivity, pyramid and efficiencies +80, currency +20, full-quarter wage impact −50, brand and partnerships −50 bps | K28: Samir Seksaria (CFO) | L28: S106 | M28: Margin stable at 25.2%; utilisation not named
A29: MW28 | B29: TCS | C29: Q1 FY26 | D29: 30 | F29: C | I29: =IF(AND(ISNUMBER(E29),ISNUMBER(H29),H29<>0),E29/H29,"") | J29: "The demand contraction during the quarter had an impact on our utilization"; offset by lower third-party costs and currency | K29: Samir Seksaria (CFO) | L29: S105 | M29: Policy quarter (cap from 12 Jun 2025); utilisation fell, not quantified
A30: MW29 | B30: TCS | C30: Q4 FY26 | D30: 10 | F30: C | I30: =IF(AND(ISNUMBER(E30),ISNUMBER(H30),H30<>0),E30/H30,"") | J30: Realisations +40, currency +110, external consultants and build −40, partner and go-to-market −50, integration −10 bps | K30: Samir Seksaria (CFO) | L30: S107 | M30: Utilisation and bench not discussed

Sheet Policy_Events
A1: event_id | B1: firm | C1: policy / event | D1: effective_date | E1: first_affected_quarter | F1: source_id | G1: analysis_use | H1: verification
A2: PE01 | B2: TCS | C2: Bench cap: 35 business days a year; 225 billable days rule | D2: 2025-06-12 | E2: Q1 FY26 (effective mid-quarter) | F2: S35;S40 | G2: Pre-period Q2 FY25–Q1 FY26 vs post Q2 FY26 onward; TCS later rebuilt bench (S36) | H2: Second source: S40 teaching case
A3: PE02 | B3: Wipro | C3: Bench window up to 180 days for Band 2 and below; 45 days for Band 3 and above | D3: 2026-10-01 | E3: Q3 FY27 (first full quarter) | F3: S34 | G3: First post-policy result: Q3 FY27, due ~Jan 2027 | H3: Single news source; seek company confirmation
A4: PE03 | B4: TCS | C4: CFO says TCS invested in a higher bench and more subcontractors | D4: 2026-10 (Q2 FY27 call) | E4: Q2 FY27 | F4: S36 | G4: Counter-evidence: policy did not keep bench low | H4: From D1
A5: PE04 | B5: TCS | C5: NITES union complaint to Ministry of Labour and Employment | D5: 2025-07 | E5: Q2 FY26 | F5: S39 | G5: Labour-relations risk context | H5: From D1

Sheet Coverage_Check
A1: Week-1 coverage check vs D1 success metrics (all figures are live formulas on Quarterly_Panel and Margin_Walks)
A3: firm | B3: firm-quarters in panel | C3: with op margin | D3: with utilisation (excl. trainees) | E3: % with utilisation | F3: first quarter | G3: last quarter
A4: Wipro | B4: =COUNTIF(Quarterly_Panel!$A$2:$A$135,A4) -> 50 | C4: =COUNTIFS(Quarterly_Panel!$A$2:$A$135,A4,Quarterly_Panel!$D$2:$D$135,"<>") -> 50 | D4: =COUNTIFS(Quarterly_Panel!$A$2:$A$135,A4,Quarterly_Panel!$F$2:$F$135,"<>") -> 50 | E4: =IF(B4=0,"",D4/B4) -> 1 | F4: =INDEX(Quarterly_Panel!$B$2:$B$135,MATCH(A4,Quarterly_Panel!$A$2:$A$135,0)) -> Q1 FY15 | G4: =INDEX(Quarterly_Panel!$B$2:$B$135,MATCH(A4,Quarterly_Panel!$A$2:$A$135,0)+B4-1) -> Q2 FY27
A5: Infosys | B5: =COUNTIF(Quarterly_Panel!$A$2:$A$135,A5) -> 30 | C5: =COUNTIFS(Quarterly_Panel!$A$2:$A$135,A5,Quarterly_Panel!$D$2:$D$135,"<>") -> 30 | D5: =COUNTIFS(Quarterly_Panel!$A$2:$A$135,A5,Quarterly_Panel!$F$2:$F$135,"<>") -> 30 | E5: =IF(B5=0,"",D5/B5) -> 1 | F5: =INDEX(Quarterly_Panel!$B$2:$B$135,MATCH(A5,Quarterly_Panel!$A$2:$A$135,0)) -> Q4 FY19 | G5: =INDEX(Quarterly_Panel!$B$2:$B$135,MATCH(A5,Quarterly_Panel!$A$2:$A$135,0)+B5-1) -> Q1 FY27
A6: TCS | B6: =COUNTIF(Quarterly_Panel!$A$2:$A$135,A6) -> 19 | C6: =COUNTIFS(Quarterly_Panel!$A$2:$A$135,A6,Quarterly_Panel!$D$2:$D$135,"<>") -> 19 | D6: =COUNTIFS(Quarterly_Panel!$A$2:$A$135,A6,Quarterly_Panel!$F$2:$F$135,"<>") -> 0 | E6: =IF(B6=0,"",D6/B6) -> 0 | F6: =INDEX(Quarterly_Panel!$B$2:$B$135,MATCH(A6,Quarterly_Panel!$A$2:$A$135,0)) -> Q4 FY22 | G6: =INDEX(Quarterly_Panel!$B$2:$B$135,MATCH(A6,Quarterly_Panel!$A$2:$A$135,0)+B6-1) -> Q2 FY27
A7: HCLTech | B7: =COUNTIF(Quarterly_Panel!$A$2:$A$135,A7) -> 9 | C7: =COUNTIFS(Quarterly_Panel!$A$2:$A$135,A7,Quarterly_Panel!$D$2:$D$135,"<>") -> 9 | D7: =COUNTIFS(Quarterly_Panel!$A$2:$A$135,A7,Quarterly_Panel!$F$2:$F$135,"<>") -> 0 | E7: =IF(B7=0,"",D7/B7) -> 0 | F7: =INDEX(Quarterly_Panel!$B$2:$B$135,MATCH(A7,Quarterly_Panel!$A$2:$A$135,0)) -> Q2 FY25 | G7: =INDEX(Quarterly_Panel!$B$2:$B$135,MATCH(A7,Quarterly_Panel!$A$2:$A$135,0)+B7-1) -> Q2 FY27
